Workbook

Sheet Sheet1
AA1: 文書番号：GM009
A2: 供給者管理リスト(車載関係用） | AA2: 承認 | AB2: 作成
C4: 更新： | D4: 45930 | AA4: 作成日 | AB4: 44207
B5: ID | C5: 供給者名（発注先） | D5: メーカー名 | E5: 新規 | F5: 継続 | G5: 管理ランク | H5: 購買品 | I5: ISO有無 | J5: 有効期限 | K5: 認証機関 | L5: 評価対象 | M5: QMS開発 | N5: 第２者監査 | O5: 供給者開発 | P5: 2024年仕入実績 | Q5: ISO取得状況 | R5: 車載関係 | S5: 関係部署 | T5: 取引内容 | U5: 発注方法 | V5: 担当者 | W5: メール | X5: 住所① | Y5: 住所② | Z5: 郵便番号 | AA5: TEL | AB5: FAX | AC5: EMail | AD5: HsuSyori | AE5: Yomi | AF5: KANAGATA | AG5: BankCod | AH5: BankName | AI5: BankSCod | AJ5: BankSName | AK5: TesuInt | AL5: BNumber | AM5: KOUZA | AN5: MyCurrency | AO5: SView | AP5: SHIHARAI | AQ5: SYANAIKAN
C6: △：ドキュメント監査 | N6: △の仕入れ先に対して、書類を送る。 | X6: 住所①
A7: 1 | B7: 85 | C7: （株）ミヤタ | D7: MAアルミニウム㈱ | E7: 44977 | F7: 45845 | G7: B | H7: 主要材料 | I7: ISO9001取得有り | J7: 46235 | K7: JSA | L7: 〇 | M7: 〇 | N7: △ | O7: × | P7: =SUMIFS('2024'!J:J,'2024'!C:C,Sheet1!D7) -> 198836389 | Q7: - | R7: 〇 | S7: 加工課 | T7: 材料 | U7: メール | V7: 佐藤・石橋 | W7: <t-sato@mi-ya-ta.co.jp>、<y-ishibashi@mi-ya-ta.co.jp> | X7: 大田区中央３丁目２１－１１ | Z7: 143-0024 | AA7: 033-773-7711 | AB7: 033-773-7710 | AD7: 0 | AE7: ミヤタ | AF7: FALSE | AH7: 横浜 | AJ7: 蒲田 | AK7: 3 | AL7: 0300040 | AM7: 2 | AN7: 0 | AO7: FALSE | AP7: 3 | AQ7: FALSE
A8: 2 | B8: 85 | C8: （株）ミヤタ | D8: ㈱プロテリアル金属 | E8: 45015 | F8: 45392 | G8: B | H8: 主要材料 | I8: ISO9001取得有り | J8: 45713 | K8: LRQAリミテッド | L8: 〇 | M8: 〇 | N8: △ | O8: × | P8: =SUMIFS('2024'!J:J,'2024'!C:C,Sheet1!D8) -> 49831705 | R8: 〇 | S8: 加工課 | T8: 材料 | U8: メール | V8: 佐藤・石橋 | W8: <t-sato@mi-ya-ta.co.jp>、<y-ishibashi@mi-ya-ta.co.jp> | X8: 大阪府吹田氏2-19-1
A9: 3 | B9: 85 | C9: （株）ミヤタ | D9: 古川電工㈱ | E9: 44967 | F9: 45397 | G9: B | H9: 主要材料 | I9: ISO9001取得有り | J9: 2026/1218 | K9: JQA | L9: 〇 | M9: 〇 | N9: △ | O9: × | P9: =SUMIFS('2024'!J:J,'2024'!C:C,Sheet1!D9) -> 29643051 | R9: 〇 | S9: 加工課 | T9: 材料 | U9: メール | V9: 佐藤・石橋 | W9: <t-sato@mi-ya-ta.co.jp>、<y-ishibashi@mi-ya-ta.co.jp>
A10: 4 | B10: 85 | C10: （株）ミヤタ | D10: 片木アルミ | E10: 44944 | F10: 45856 | G10: B | H10: 主要材料 | I10: ISO9001取得無し | L10: 〇 | M10: 〇 | N10: 〇 | O10: 〇 | P10: =SUMIFS('2024'!J:J,'2024'!C:C,Sheet1!D10) -> 236368 | R10: 〇 | S10: 加工課 | T10: 材料 | U10: メール | V10: 佐藤・石橋 | W10: <t-sato@mi-ya-ta.co.jp>、<y-ishibashi@mi-ya-ta.co.jp>
A11: 5 | B11: 85 | C11: （株）ミヤタ | D11: 大同特殊鋼㈱ | E11: 44951 | G11: B | H11: 主要材料 | I11: ISO9001取得有り | J11: 46784 | K11: JICQA | L11: 〇 | M11: 〇 | N11: △ | O11: × | P11: =SUMIFS('2024'!J:J,'2024'!C:C,Sheet1!D11) -> 623186 | R11: 〇 | S11: 加工課 | T11: 材料 | U11: メール | V11: 佐藤・石橋 | W11: <t-sato@mi-ya-ta.co.jp>、<y-ishibashi@mi-ya-ta.co.jp>
A12: 6 | B12: 1055 | C12: 阪和興業（株） | D12: ＣＳＡＣ(台湾メーカー) | E12: 44958 | F12: 45863 | G12: B | H12: 主要材料 | I12: ISO9001取得有り | J12: 46299 | K12: SGS | L12: 〇 | M12: 〇 | N12: △ | O12: × | P12: =SUMIFS('2024'!J:J,'2024'!C:C,Sheet1!D12) -> 49332338 | Q12: - | R12: 〇 | S12: 加工課 | T12: 材料 | U12: メール | V12: 平瀬 | W12: hirase-keito@hanwa.co.jp | X12: - | Y12: - | Z12: - | AA12: 03-3544-2329 | AB12: 03-3544-2148 | AD12: 0 | AE12: ﾊﾝﾜｺｳｷﾞｮｳ | AF12: FALSE | AH12: 三井住友 | AJ12: 東京中央 | AK12: 3 | AL12: 267225 | AM12: 2 | AN12: 0 | AO12: FALSE | AP12: 3 | AQ12: FALSE
A13: 7 | B13: 589 | C13: ㈱東電化 | D13: 製品めっき(材料先メッキ） | E13: 44974 | G13: B | H13: 主要材料 | I13: ISO9001取得有り | J13: 46431 | K13: ASR | L13: 〇 | M13: 〇 | N13: △ | O13: × | P13: - | Q13: 加工課 | R13: 〇 | S13: 加工課 | U13: ミヤタへ手配 | V13: ミヤタへ手配 | W13: - | X13: - | Y13: -
A14: 8 | B14: 969 | C14: 東栄電化工業㈱ | D14: アルマイト外注 | E14: 44937 | F14: 45870 | G14: B | H14: 主要材料 | I14: ISO9001取得有り | J14: 45824 | K14: JIC | L14: 〇 | M14: 〇 | N14: △ | O14: × | P14: =SUMIFS('2024'!J:J,'2024'!C:C,Sheet1!C14) -> 1699686 | Q14: 加工課 | R14: 〇 | S14: 加工課 | T14: アルマイト | U14: メールorFAX | V14: 小林・田淵 | W14: <sada@toeidenka.co.jp>、<tabuchi@toeidenka.co.jp> | X14: 相模原市中央区小町通2-5-9 | Y14: 042-771-1528 | Z14: 042-773-4032 | AA14: 042-771-1528 | AB14: 042-773-4032
A15: 9 | B15: 418 | C15: 東京材料㈱ | D15: 石塚化学 | E15: 44967 | G15: B | H15: 主要材料 | I15: ISO9001取得有り | J15: 45947 | K15: ASR | L15: 〇 | M15: 〇 | N15: △ | O15: × | P15: =SUMIFS('2024'!J:J,'2024'!C:C,Sheet1!D15) -> 18456325 | R15: 〇 | S15: 加工課 | U15: メール | V15: 吉田 | W15: yusuke.yoshida@tokyozairyo.co.jp
A16: 10 | B16: 1095 | C16: 日本ケミカル電子㈱ | D16: 試作品のめっき | E16: 44993 | F16: 45611 | G16: B | H16: 主要材料 | I16: ISO9001取得有り | J16: 46133 | K16: JQA | L16: 〇 | M16: 〇 | N16: △ | O16: × | P16: =SUMIFS('2024'!J:J,'2024'!C:C,Sheet1!C16) -> 1699686 | Q16: ISO9001 | R16: △ | S16: 加工課 | T16: メッキ | U16: メール | V16: 早川 | W16: <hayakawa@jp-ncd.com> | X16: - | Y16: - | Z16: - | AA16: 0561-54-1234 | AB16: 0561-54-9101 | AD16: 0 | AE16: ﾆﾎﾝｹﾐｶﾙ | AF16: FALSE | AK16: 1 | AM16: 1 | AN16: 0 | AO16: FALSE | AP16: 3 | AQ16: FALSE
A17: 11 | B17: 37 | C17: （株）三松（表面処理薬品商社） | D17: ユケン工業㈱ | E17: 44967 | F17: 45772 | G17: B | H17: 一般購買品 | I17: ISO9001取得有り | J17: 45411 | K17: JCQA | L17: 〇 | M17: 〇 | N17: △ | O17: × | P17: =SUMIFS('2024'!J:J,'2024'!C:C,Sheet1!D17) -> 1842500 | Q17: ISO9001 | R17: △ | S17: 加工課 | T17: 薬品 | U17: FAX | V17: 岡田 | W17: n-okada@sanmatu.co.jp | X17: 東京都大田区西蒲田7-57-11 | Z17: 144-0051 | AA17: 033-733-7131 | AB17: 033-739-0321 | AD17: 0 | AE17: ｻﾝﾏﾂ | AF17: FALSE | AH17: 三菱東京UFJ銀行 | AJ17: カマタエキマエ | AK17: 3 | AL17: 0001125 | AM17: 2 | AN17: 0 | AO17: FALSE | AP17: 3 | AQ17: FALSE
A18: 12 | B18: 1033 | C18: クリンビー | D18: 東ソー株式会社 | E18: 44951 | G18: B | H18: 主要材料 | I18: ISO9001取得有り | J18: 46377 | K18: UKAS | L18: 〇 | M18: 〇 | N18: △ | O18: × | P18: =SUMIFS('2024'!J:J,'2024'!C:C,Sheet1!D18) -> 848000 | Q18: ISO9001 | R18: △ | S18: 加工課 | T18: 薬品 | U18: FAX | V18: 小林 | W18: yo_kobayashi@cleanvy-jp.com | X18: 長野県諏訪市四賀3011-3 | AA18: 0266-57-0521 | AB18: 0266-52-5191
A19: 13 | B19: 928 | C19: 新日本化成㈱ | D19: 日産化学（硝酸） | E19: 44938 | F19: 45877 | G19: B | H19: 主要材料 | I19: ISO9001取得有り | L19: 〇 | M19: × | N19: × | O19: × | P19: =SUMIFS('2024'!J:J,'2024'!C:C,Sheet1!C19) -> 120000 | Q19: ISO9001 | R19: 〇 | S19: 加工課 | T19: 薬品 | U19: FAX | X19: 厚木市中依知348-1 | Z19: 243-0805 | AA19: 046-210-3999 | AB19: 046-245-4125 | AD19: 0 | AE19: ｼﾝﾆﾎﾝｶｾｲ | AF19: FALSE | AH19: 千葉銀行 | AJ19: 京成駅前 | AK19: 3 | AL19: 1243506 | AM19: 1 | AN19: 0 | AO19: FALSE | AP19: 3 | AQ19: FALSE
A20: 14 | B20: 79 | C20: （株）ミスミ | D20: 金型パーツ | E20: 44956 | F20: 45866 | G20: B | H20: 一般購買品 | I20: ISO9001取得無し | L20: 〇 | M20: × | N20: × | O20: × | P20: =SUMIFS('2024'!J:J,'2024'!C:C,Sheet1!C20) -> 17969191 | Q20: ISO14001 | R20: 〇 | S20: 工場全般 | T20: 消耗品・自動機部品・金型部品 | U20: WEB | X20: 横浜市神奈川区鶴屋町3-31-5 | Y20: 久保田ビル4F | Z20: 221-0831 | AA20: 045-324-1141 | AB20: 045-324-0252 | AD20: 0 | AE20: ミスミ | AF20: FALSE | AH20: みずほ銀行 | AJ20: ダイニシユウチュウ | AK20: 3 | AL20: 1073861 | AM20: 2 | AN20: 0 | AO20: FALSE | AP20: 3 | AQ20: FALSE
A21: 15 | B21: 95 | C21: 新日本精機㈱ | D21: システム管理 | G21: B | H21: 一般購買品 | I21: ISO9001取得無し | L21: 〇 | M21: × | N21: × | O21: × | P21: =SUMIFS('2024'!J:J,'2024'!C:C,Sheet1!D21) -> 0 | Q21: - | R21: 〇 | S21: 加工課 | T21: 内職 | X21: 平塚市大島1294-1 | Z21: 254-0001 | AA21: 0463-51-1010 | AB21: 0463-54-5827 | AD21: 0 | AE21: シンニホン | AF21: FALSE | AH21: 静岡中央銀行 | AJ21: 平塚 | AK21: 3 | AL21: 1982131 | AM21: 1 | AN21: 0 | AO21: FALSE | AP21: 3 | AQ21: FALSE
A22: 16 | B22: 377 | C22: 東海鋼鉄㈱ | D22: 金型のプレートの購入 | E22: 44967 | F22: 45761 | G22: B | H22: 一般購買品 | I22: ISO9001取得無し | L22: 〇 | M22: × | N22: × | O22: × | P22: =SUMIFS('2024'!J:J,'2024'!C:C,Sheet1!C22) -> 4928081 | Q22: なし | R22: 〇 | S22: 技術部 | T22: プレート | U22: メールorFAX | V22: 榎本 | W22: <sa-8@toukaikoutetsu.com> | X22: 綾瀬市吉岡278 | AA22: 0467-78-0721 | AB22: 0467-76-2747 | AD22: 0 | AE22: ﾄｳｶｲｺｳﾃﾂ | AF22: FALSE | AH22: 三菱東京UFJ | AJ22: ヤマト | AK22: 3 | AL22: 0170269 | AM22: 2 | AN22: 0 | AO22: FALSE | AP22: 3 | AQ22: FALSE
A23: 17 | B23: 363 | C23: 藤沢紙工㈱ | D23: 製品保護のためのジャバラ紙 | E23: 44944 | G23: B | H23: 一般購買品 | I23: ISO9001取得無し | L23: × | M23: × | N23: × | O23: × | P23: =SUMIFS('2024'!J:J,'2024'!C:C,Sheet1!C23) -> 78168 | Q23: ISO9001/ISO14001 | R23: 〇 | S23: 加工課 | T23: パーチメント紙 ・コーナーアングル | U23: FAX | V23: 前澤 | W23: <y.maezawa.fujikoo@gmail.com> | X23: 茅ヶ崎市中島1158-6 | Z23: 253-0073 | AA23: 0467-58-2600 | AB23: 0467-58-2607 | AD23: 0 | AE23: ﾌｼﾞｻﾜｼｺｳ | AF23: FALSE | AH23: 三菱東京ＵＦＪ | AJ23: 藤沢 | AK23: 3 | AL23: 9005803 | AM23: 2 | AN23: 0 | AO23: FALSE | AP23: 3 | AQ23: FALSE
A24: 18 | B24: 260 | C24: パンチ工業 ㈱ | D24: 金型のパンチ等購入 | E24: 45002 | F24: 45821 | G24: B | H24: 一般購買品 | I24: ISO9001取得有り | L24: 〇 | M24: × | N24: × | O24: × | P24: =SUMIFS('2024'!J:J,'2024'!C:C,Sheet1!C24) -> 3836641 | Q24: ISO9001,ISO14001 | R24: 〇 | S24: 技術部 | T24: 金型パーツ | U24: WEB | V24: - | W24: - | X24: 本）品川区南大井6-22-7大森ベルポートＥ-5Ｆ | AA24: （045）904-8007 | AB24: 045-904-8011 | AD24: 0 | AE24: ﾊﾟﾝﾁｺｳｷﾞｮｳ | AF24: FALSE | AH24: りそな | AJ24: 品川 | AK24: 3 | AL24: 6002835 | AM24: 2 | AN24: 0 | AO24: FALSE | AP24: 3 | AQ24: FALSE
A25: 19 | B25: 473 | C25: ㈱橋本工商 | D25: 工作機械・工具など | E25: 44993 | F25: 45506 | G25: B | H25: 一般購買品 | I25: ISO9001取得無し | L25: 〇 | M25: × | N25: × | O25: × | P25: =SUMIFS('2024'!J:J,'2024'!C:C,Sheet1!C25) -> 6803335 | Q25: ISO14001 | R25: 〇 | S25: 技術部 | T25: 消耗品工具 | U25: メールorFAX | V25: 中基 | W25: chk-nakamoto@jcom.home.ne.jp | X25: 相模原市中央区高根1-14-7 | Z25: 252-0221 | AA25: 042-759-4001 | AB25: 042-759-4003 | AD25: 0 | AE25: ﾊｼﾓﾄｺｳｼｮｳ | AF25: FALSE | AH25: ミズホ | AJ25: 相模原 | AK25: 3 | AL25: 1334087 | AM25: 1 | AN25: 0 | AO25: FALSE | AP25: 3 | AQ25: FALSE
A26: 20 | B26: 1056 | C26: 東京プロト㈱ | D26: 梱包製品トレイ | E26: 44984 | F26: 45891 | G26: B | H26: 一般購買品 | I26: ISO9001取得有り | L26: 〇 | M26: × | N26: × | O26: × | P26: =SUMIFS('2024'!J:J,'2024'!C:C,Sheet1!C26) -> 23282660 | Q26: ISO9001,ISO14001 | R26: 〇 | S26: 加工課 | T26: トレイ | U26: メールorFAX | V26: 田内 | W26: tauchi@tokyoproto.co.jp | X26: 横浜市港北区樽町3-1-1 | Z26: 222-0001 | AA26: 045-543-0141 | AB26: 045-562-9882 | AD26: 0 | AE26: ﾄｳｷｮｳﾌﾟﾛﾄ | AF26: FALSE | AH26: 横浜 | AJ26: 大倉山 | AK26: 3 | AL26: 5159 | AM26: 2 | AN26: 0 | AO26: FALSE | AP26: 3 | AQ26: FALSE
A27: 21 | B27: 62 | C27: 日興運送（株） | D27: 運送 | E27: 44985 | F27: 45896 | G27: B | H27: 一般購買品 | I27: ISO9001取得無し | L27: 〇 | M27: × | N27: △ | O27: × | P27: 11184417 | Q27: ISO14001 | R27: 〇 | S27: 加工課 | T27: 輸送 | X27: 茨城県土浦市荒川沖東2-10-34 | Z27: 300-1171 | AA27: 0298-41-2138 | AB27: 0298-41-1966 | AD27: 0 | AE27: ニッコウ | AF27: FALSE | AH27: 三井住友 | AJ27: つくば | AK27: 3 | AL27: 0212504 | AM27: 1 | AN27: 0 | AO27: FALSE | AP27: 3 | AQ27: FALSE
A28: 22 | B28: 683 | C28: 日本アレックス㈱ | D28: 超音波振動子ユニット | E28: 44994 | F28: 45896 | G28: B | H28: 一般購買品 | I28: ISO9001取得無し | L28: 〇 | M28: × | N28: × | O28: × | P28: =SUMIFS('2024'!J:J,'2024'!C:C,Sheet1!C28) -> 85000 | R28: 〇 | S28: 加工課 | T28: 超音波 | U28: メールorFAX | V28: 遠山 | W28: toyama@nalex.co.jp | AD28: 0 | AE28: ﾆﾎﾝ | AF28: FALSE | AK28: 1 | AM28: 普通 | AN28: 0 | AO28: FALSE | AP28: 3 | AQ28: FALSE
A29: 23 | B29: 983 | C29: タイヨー㈱ | D29: 製品梱包段ボール | E29: 44953 | F29: 45905 | G29: B | H29: 一般購買品 | I29: ISO9001取得有り | L29: 〇 | M29: × | N29: △ | O29: × | P29: =SUMIFS('2024'!J:J,'2024'!C:C,Sheet1!C29) -> 2798957 | Q29: ISO9001,ISO14001 | R29: 〇 | S29: 加工課 | T29: 段ボール | U29: FAX | X29: 神奈川県厚木市温水1961 | Z29: 243-0033 | AA29: 046-248-8511 | AB29: 046-247-3357 | AD29: 0 | AE29: ﾀｲﾖｰ | AF29: FALSE | AH29: 三井住友 | AJ29: 厚木 | AK29: 3 | AL29: 1022846 | AM29: 2 | AN29: 0 | AO29: FALSE | AP29: 3 | AQ29: FALSE
A30: 24 | B30: 447 | C30: ㈱キーエンス | D30: 測定器 | E30: 44977 | G30: B | H30: 一般購買品 | I30: ISO9001取得無し | L30: 〇 | M30: × | N30: × | O30: × | P30: =SUMIFS('2024'!J:J,'2024'!C:C,Sheet1!C30) -> 5008320 | R30: 〇 | S30: 生産技術 | T30: 自動機部品 | U30: FAX | V30: - | W30: - | X30: 海老名市中央2-9-50 | Y30: 海老名プライムタワー13Ｆ | Z30: 243-0432 | AA30: 046-236-0755 | AB30: 046-236-0766 | AD30: 0 | AE30: ｷｰｴﾝｽ | AF30: TRUE | AH30: 三井住友 | AJ30: ウメダ | AK30: 3 | AL30: 0222375 | AM30: 2 | AN30: 0 | AO30: FALSE | AP30: 3 | AQ30: FALSE
A31: 25 | B31: 130 | C31: ミドリ安全厚木㈱ | D31: 作業着、帽子、安全靴の商社 | E31: 44858 | G31: B | H31: 一般購買品 | I31: ISO9001取得無し | L31: × | M31: × | N31: × | O31: × | P31: =SUMIFS('2024'!J:J,'2024'!C:C,Sheet1!C31) -> 1936830 | Q31: ISO9001/ISO14001 | R31: 〇 | S31: 工場全般 | T31: 作業 | U31: FAX | X31: 厚木市水引2-11-2 | Z31: 243-0004 | AA31: 046-223-1771 | AB31: 046-223-6377 | AD31: 0 | AE31: ﾐﾄﾞﾘｱﾝｾﾞﾝ | AF31: FALSE | AH31: ヨコハマ | AJ31: カモメ | AK31: 3 | AL31: 0501194 | AM31: 1 | AN31: 0 | AO31: FALSE | AP31: 3 | AQ31: FALSE
A32: 26 | B32: 83 | C32: リヒト精光（株） | D32: 金型パーツの焼き入れ業者 | E32: 45015 | G32: B | H32: 一般購買品 | I32: ISO9001取得有り | L32: 〇 | M32: × | N32: × | O32: × | P32: =SUMIFS('2024'!J:J,'2024'!C:C,Sheet1!C32) -> 2976600 | Q32: ISO9001 | R32: 〇 | S32: 技術部 | T32: 熱処理 | U32: - | X32: 厚木市下依知1-12-23 | Z32: 243-0806 | AA32: 046-245-1611 | AB32: 046-245-1610 | AD32: 0 | AE32: リヒト | AF32: TRUE | AH32: みずほ銀行 | AJ32: 厚木 | AK32: 3 | AL32: 0812193 | AM32: 1 | AN32: 0 | AO32: FALSE | AP32: 3 | AQ32: FALSE
A33: 27 | B33: 141 | C33: 新共立化工㈱ | D33: 表面処理ライン保守などのパーツ | E33: 45005 | F33: 45910 | G33: B | H33: 一般購買品 | I33: ISO9001取得無し | L33: 〇 | M33: × | N33: × | O33: × | P33: =SUMIFS('2024'!J:J,'2024'!C:C,Sheet1!C33) -> 36545 | Q33: - | R33: 〇 | S33: 加工課 | T33: 塩ビ板 | U33: FAX | X33: 埼玉県川口市上青木 | Y33: 2丁目22番6号 | Z33: 333 | AA33: 048-269-2726 | AB33: 048-267-7382 | AD33: 0 | AE33: ｼﾝｷｮｳﾘﾂｶｺｳ | AF33: FALSE | AH33: 三菱東京UFJ | AJ33: 西川口 | AK33: 3 | AL33: 9012495 | AM33: 2 | AN33: 0 | AO33: FALSE | AP33: 3 | AQ33: FALSE
A34: 28 | B34: 1062 | C34: ㈱モノタロウ | D34: 部品など | E34: 45009 | F34: 45779 | G34: B | H34: 一般購買品 | I34: ISO9001取得無し | L34: 〇 | M34: 〇 | N34: × | O34: × | P34: =SUMIFS('2024'!J:J,'2024'!C:C,Sheet1!C34) -> 5122693 | R34: 〇 | S34: 工場全般 | T34: 消耗品 | U34: WEB | X34: 兵庫県尼崎市竹谷町2-183 | Y34: リベル3階 | Z34: 660-0876 | AA34: 0120-443-509 | AB34: 0120-289-888 | AD34: 0 | AE34: ﾓﾉ | AF34: FALSE | AH34: 三井住友 | AJ34: ドットコム | AK34: 3 | AL34: 9070269 | AM34: 1 | AN34: 0 | AO34: FALSE | AP34: 3 | AQ34: FALSE
A35: 29 | B35: 73 | C35: 双葉電子工業（株） | D35: 金型のプレートの購入 | E35: 44991 | F35: 45917 | G35: B | H35: 一般購買品 | I35: ISO9001取得有り | L35: 〇 | M35: × | N35: × | O35: × | P35: =SUMIFS('2024'!J:J,'2024'!C:C,Sheet1!C35) -> 4763331 | Q35: ISO9001/ISO14001 | R35: 〇 | S35: 技術部 | T35: プレート | U35: FAX | X35: 東京都墨田区堤通一丁目19番9号 | Y35: リバーサイド隅田セントラルタワー16階 | Z35: 131-0034 | AA35: 03-3616-1730 | AB35: 03-3616-1731 | AD35: 0 | AE35: フタバ | AF35: FALSE | AH35: チバ | AJ35: モバラ | AK35: 3 | AL35: 2189623 | AM35: 1 | AN35: 0 | AO35: FALSE | AP35: 3 | AQ35: FALSE
A36: 30 | B36: 140 | C36: トヨタエルアンドエフ | D36: フォークリスト、海外出荷用パレット | E36: 44956 | F36: 45924 | G36: B | H36: 一般購買品 | I36: ISO9001取得有り | L36: 〇 | M36: × | N36: × | O36: × | P36: =SUMIFS('2024'!J:J,'2024'!C:C,Sheet1!C36) -> 457600 | Q36: ISO9001,ISO14001 | R36: 〇 | S36: 加工課 | T36: フォークリフト・パレット | U36: FAX | X36: 厚木市金田６８８－１ | Z36: 243-0807 | AA36: 046-224-1231 | AB36: 046-224-1237 | AD36: 0 | AE36: ﾄﾖﾀ | AF36: FALSE | AH36: 三菱東京ＵＦＪ | AJ36: トウキョウカワセシュウチュウ | AK36: 3 | AL36: 4479700 | AM36: 1 | AN36: 0 | AO36: FALSE | AP36: 3 | AQ36: FALSE
A37: 31 | B37: 549 | C37: イースタン技研㈱ | D37: ワイヤー電極線 | E37: 44953 | F37: 45926 | G37: B | H37: 一般購買品 | I37: ISO9001取得有り | L37: 〇 | M37: × | N37: × | O37: × | P37: =SUMIFS('2024'!J:J,'2024'!C:C,Sheet1!C37) -> 3328460 | Q37: ISO9001,ISO14001 | R37: 〇 | S37: 技術部 | T37: 消耗品 | U37: FAX | X37: 大和市福田6-9-21 | Z37: 242-0024 | AA37: 046-268-3131 | AB37: 046-268-2284 | AD37: 0 | AE37: ｲｰｽﾀﾝ | AF37: FALSE | AH37: 横浜 | AJ37: サガミオオノ | AK37: 3 | AL37: 0015765 | AM37: 2 | AN37: 0 | AO37: FALSE | AP37: 3 | AQ37: FALSE
A38: 32 | B38: 334 | C38: 東京ワイジェーエス販売 | D38: 商社 色々なものを購入している | E38: 45014 | F38: 45930 | G38: B | H38: 一般購買品 | I38: ISO9001取得無し | L38: 〇 | M38: 〇 | N38: △ | O38: × | P38: =SUMIFS('2024'!J:J,'2024'!C:C,Sheet1!C38) -> 963800 | R38: 〇 | S38: 技術部 | T38: 加工機部品 | U38: FAX | X38: 藤沢氏本藤沢3-5-17 | Z38: 251-0875 | AA38: 0466-80-6160 | AB38: 0466-80-6260 | AD38: 0 | AE38: ﾄｳｷｮｳﾜｲ | AF38: FALSE | AH38: かながわ信用金庫 | AJ38: ホンチョウ | AK38: 3 | AL38: 1975647 | AM38: 1 | AN38: 0 | AO38: FALSE | AP38: 3 | AQ38: FALSE
A39: 33 | B39: 1053 | C39: ＭＩＣＳ化学 | D39: 製品梱包包装用ビニール | E39: 44986 | F39: 45565 | G39: B | H39: 一般購買品 | I39: ISO9001取得有り | L39: 〇 | M39: × | N39: × | O39: × | P39: =SUMIFS('2024'!J:J,'2024'!C:C,Sheet1!C39) -> 0 | Q39: ISO9001 | R39: 〇 | S39: 加工課 | T39: ﾋﾞﾆｰﾙ袋 | U39: FAX | X39: 愛知県愛知郡東郷町諸輪北山158-89 | Y39: - | Z39: 470-0151 | AA39: 03-3667-6788 | AB39: 03-3667-6789 | AD39: 0 | AE39: ﾐｯｸｽｶｶﾞｸ | AF39: FALSE | AH39: 三井住友 | AJ39: 名古屋 | AK39: 3 | AL39: 7229378 | AM39: 1 | AN39: 0 | AO39: FALSE | AP39: 3 | AQ39: FALSE
A40: 34 | B40: 464 | C40: ㈱共立合金製作所 | D40: 金型用プレート | E40: 44960 | F40: 45576 | G40: B | H40: 一般購買品 | I40: ISO9001取得有り | L40: 〇 | M40: × | N40: × | O40: × | P40: =SUMIFS('2024'!J:J,'2024'!C:C,Sheet1!C40) -> 2327800 | Q40: ISO9001,ISO14001 | R40: 〇 | S40: 技術部 | T40: 超硬材 | U40: FAX | V40: 牧野 俊輔 | W40: <s-makino@everloy.co.jp> | AA40: 0798-26-3606 | AB40: 0798-37-2067 | AD40: 0 | AE40: ｷｮｳﾘﾂｺﾞｳｷﾝ | AF40: FALSE | AH40: 三菱東京UFJ | AJ40: ニシノミヤ | AK40: 3 | AL40: 1006180 | AM40: 1 | AN40: 0 | AO40: FALSE | AP40: 3 | AQ40: FALSE
A41: 35 | B41: 1047 | C41: ㈱マルアイ | D41: 製品梱包包装用ビニール | E41: 45005 | F41: 45576 | G41: B | H41: 一般購買品 | I41: ISO9001取得有り | L41: 〇 | M41: × | N41: × | O41: × | P41: =SUMIFS('2024'!J:J,'2024'!C:C,Sheet1!C41) -> 161340 | Q41: ISO9001,ISO14001 | R41: 〇 | S41: 加工課 | T41: ﾋﾞﾆｰﾙ袋 | U41: FAX | V41: 古屋 | W41: t.furuya@maruai.co.jp | X41: - | Y41: - | Z41: - | AA41: - | AB41: 055-272-4481 | AD41: 0 | AE41: ﾏﾙｱｲ | AF41: FALSE | AK41: 1 | AM41: 1 | AN41: 0 | AO41: FALSE | AP41: 3 | AQ41: FALSE
...

Sheet 2024
B1: ２０２４年度
B3: 調査日 | D3: 45662
B4: 項番 | C4: 供給者 | D4: 購入品 | E4: 最終購入日 | F4: 最終購入日からの経過日数 | G4: R値 | H4: 累計購入回数 | I4: F値 | J4: 累積購入金額 | K4: M値 | L4: 総合点数 | M4: ランク | O4: R値：最終購入日 | Q4: F値：購入回数 | S4: M値：購入金額
B5: 1 | C5: MAアルミニウム㈱ | D5: A1050-H24 | E5: 45652 | F5: 10 | G5: 5 | H5: 81 | I5: 4 | J5: 198335080 | K5: 5 | L5: 14 | M5: B | O5: 5 | P5: 最終購入日３０日未満 | Q5: 5 | R5: 100回以上 | S5: 5 | T5: １千万円以上
B6: 2 | C6: MAアルミニウム㈱ | D6: A5052-H34 | E6: 45446 | F6: 216 | G6: 1 | H6: 3 | I6: 1 | J6: 501309 | K6: 1 | L6: 3 | M6: F | O6: 4 | P6: 最終購入日６０日未満 | Q6: 4 | R6: 70回以上 | S6: 4 | T6: ５００万円以上
B7: 3 | C7: 古川電工㈱ | D7: C1020-1/2H | E7: 45621 | F7: 41 | G7: 4 | H7: 12 | I7: 1 | J7: 29643051 | K7: 5 | L7: 10 | M7: C | O7: 3 | P7: 最終購入日９０日未満 | Q7: 3 | R7: 50回以上 | S7: 3 | T7: 300万円以上
B8: 4 | C8: ㈱プロテリアル金属 | D8: Ni201-1/2H | E8: 45646 | F8: 16 | G8: 5 | H8: 10 | I8: 1 | J8: 49831705 | K8: 5 | L8: 11 | M8: C | O8: 2 | P8: 最終購入日180日未満 | Q8: 2 | R8: 30回以上 | S8: 2 | T8: １００万円以上
B9: 5 | C9: 大同特殊鋼㈱ | D9: Ni201-1/2H | E9: 45495 | F9: 167 | G9: 2 | H9: 2 | I9: 1 | J9: 623186 | K9: 1 | L9: 4 | M9: F | O9: 1 | P9: 最終購入日181日以上 | Q9: 1 | R9: 29回以下 | S9: 1 | T9: 99万円以下
B10: 6 | C10: 片木アルミ | D10: A1050-H24 | E10: 45639 | F10: 23 | G10: 5 | H10: 1 | I10: 1 | J10: 236368 | K10: 1 | L10: 7 | M10: C
B11: 7 | C11: ＣＳＡＣ(台湾メーカー) | D11: A1050-H24 | E11: 45653 | F11: 9 | G11: 5 | H11: 87 | I11: 4 | J11: 38346348 | K11: 5 | L11: 14 | M11: B
B12: 8 | C12: ＣＳＡＣ(台湾メーカー) | D12: A5052-H34 | E12: 45639 | F12: 23 | G12: 5 | H12: 37 | I12: 2 | J12: 10985990 | K12: 5 | L12: 12 | M12: C | O12: 15点 | P12: A
B13: 9 | C13: 石塚化学 | D13: AY564 | E13: 45643 | F13: 19 | G13: 5 | H13: 55 | I13: 3 | J13: 18456325 | K13: 5 | L13: 13 | M13: B | O13: １３点 | P13: B
B14: 10 | C14: 岡田紙業 | D14: FRA7507OP MP-6 | E14: 45651 | F14: 11 | G14: 5 | H14: 4 | I14: 1 | J14: 262360 | K14: 1 | L14: 7 | M14: C | O14: ７点 | P14: C
B15: 11 | C15: ユケン工業㈱ | D15: FD102N | E15: 45645 | F15: 17 | G15: 5 | H15: 10 | I15: 1 | J15: 1842500 | K15: 2 | L15: 8 | M15: C | O15: 5点 | P15: D
B16: 12 | C16: 新日本化成㈱ | D16: 硝酸 | E16: 45642 | F16: 20 | G16: 5 | H16: 5 | I16: 1 | J16: 120000 | K16: 1 | L16: 7 | M16: C | O16: 4点以下 | P16: F
B17: 13 | C17: 東京プロト㈱ | D17: トレイ | E17: 45651 | F17: 11 | G17: 5 | H17: 60 | I17: 3 | J17: 23282660 | K17: 5 | L17: 13 | M17: B
B18: 14 | C18: 東ソー株式会社 | D18: HC-370 | E18: 45637 | F18: 25 | G18: 5 | H18: 6 | I18: 1 | J18: 848000 | K18: 1 | L18: 7 | M18: C
B19: 15 | C19: タイヨー㈱ | D19: ダンボール、紙 | E19: 45651 | F19: 11 | G19: 5 | H19: 159 | I19: 5 | J19: 2798957 | K19: 2 | L19: 12 | M19: C
B20: 16 | C20: 東海鋼鉄㈱ | D20: 金属プレート | E20: 45639 | F20: 23 | G20: 5 | H20: 382 | I20: 5 | J20: 4928081 | K20: 3 | L20: 13 | M20: B
B21: 17 | C21: パンチ工業 ㈱ | D21: 金型パーツ | E21: 45652 | F21: 10 | G21: 5 | H21: 333 | I21: 5 | J21: 3836641 | K21: 3 | L21: 13 | M21: B
B22: 18 | C22: 東栄電化工業㈱ | D22: アルマイト | E22: 45651 | F22: 11 | G22: 5 | H22: 26 | I22: 1 | J22: 1699686 | K22: 2 | L22: 8 | M22: C
B23: 19 | C23: 日本ケミカル電子㈱ | D23: メッキ | E23: 45650 | F23: 12 | G23: 5 | H23: 23 | I23: 1 | J23: 1699686 | K23: 2 | L23: 8 | M23: C
B24: 20 | C24: 藤沢紙工㈱ | D24: コーナーアングル | E24: 45650 | F24: 12 | G24: 5 | H24: 4 | I24: 1 | J24: 78168 | K24: 1 | L24: 7 | M24: C
B25: 21 | C25: 双葉電子工業（株） | D25: 金型部品、プレート | E25: 45602 | F25: 60 | G25: 3 | H25: 46 | I25: 2 | J25: 4763331 | K25: 3 | L25: 8 | M25: C
B26: 22 | C26: キョクサン | D26: ウエス | E26: 45637 | F26: 25 | G26: 5 | H26: 10 | I26: 1 | J26: 113600 | K26: 1 | L26: 7 | M26: C
B27: 23 | C27: 日本コーティングセンター | D27: パーツコーティング | E27: 45559 | F27: 103 | G27: 2 | H27: 20 | I27: 1 | J27: 216350 | K27: 1 | L27: 4 | M27: F
B28: 24 | C28: ㈱マルアイ | D28: ビニール袋 | E28: 45607 | F28: 55 | G28: 4 | H28: 2 | I28: 1 | J28: 161340 | K28: 1 | L28: 6 | M28: D
... B64: 60 | C64: アルミネ | D64: A1100-H24 | E64: 45621 | F64: 41 | G64: 4 | H64: 3 | I64: 1 | J64: 539263 | K64: 1 | L64: 6 | M64: D
